<?xml version="1.0" encoding="utf-8"?>
<robot name="arm4dof">
 
 <link name="base_link">
  <visual name="base_visual">
   <origin rpy="0 0 0" xyz="0 0 0.02"/>
   <geometry>
    <cylinder length="0.04" radius="0.05"/>
			</geometry>
   <material name="gray_color">
    <color rgba="0.9 0.9 0.9 1"/>
   </material>
		</visual>
  <collision>
   <origin rpy="0 0 0" xyz="0 0 0.02"/>
   <geometry>
    <cylinder length="0.04" radius="0.05"/>
			</geometry>
		</collision>
	</link>

 <joint name="joint1" type="revolute">
  <parent link="base_link"/>
  <child link="shoulder"/>
  <origin rpy="0 0 0" xyz="0 0 0.040"/>
  <axis xyz="0 0 1"/>
  <limit lower="-3.14" upper="3.14" effort="0" velocity="0"/>
 </joint>
 
 <link name="shoulder">
  <visual name="shoulder_visual">
   <origin rpy="0 0 0" xyz="0 0 0.003"/>
			<geometry>
    <cylinder length="0.006" radius="0.01"/>
			</geometry>
		</visual>
  <collision>
   <origin rpy="0 0 0" xyz="0 0 0.003"/>
			<geometry>
    <cylinder length="0.006" radius="0.01"/>
			</geometry>
		</collision>
	</link>

 <joint name="joint2" type="revolute">
  <parent link="shoulder"/>
  <child link="upperarm"/>
  <origin rpy="0 0 0" xyz="0 0 0.029"/>
  <axis xyz="0 1 0"/>
  <limit lower="-1.5708" upper="1.5708" effort="0" velocity="0"/>
 </joint>
 
	<link name="upperarm">
		<visual name="upperarm_visual">
   <origin rpy="0 0 0" xyz="0 0 0.045785"/>
			<geometry>
    <box size="0.02473 0.036 0.11180"/>
			</geometry>
   <material name="gray_color">
    <color rgba="0.9 0.9 0.9 1"/>
   </material>
		</visual>
		<collision>
   <origin rpy="0 0 0" xyz="0 0 0.045785"/>
			<geometry>
    <box size="0.02473 0.036 0.11180"/>
			</geometry>
		</collision>
	</link>

 <joint name="joint3" type="revolute">
  <parent link="upperarm"/>
  <child link="forearm"/>
  <origin rpy="0 0 0" xyz="0 0 0.09157"/>
  <axis xyz="0 1 0"/>
  <limit lower="-1.5708" upper="1.5708" effort="0" velocity="0"/>
 </joint>
 
	<link name="forearm">
		<visual name="forearm_visual">
   <origin rpy="0 0 0" xyz="0 0 0.05"/>
			<geometry>
    <box size="0.02473 0.036 0.124"/>
			</geometry>
		</visual>
		<collision>
   <origin rpy="0 0 0" xyz="0 0 0.05"/>
			<geometry>
    <box size="0.02473 0.036 0.124"/>
			</geometry>
		</collision>
	</link>

 <link name="hand">
  <visual name="hand_visual">
   <origin rpy="0 0 0" xyz="0 0 0.0345175"/>
			<geometry>
    <box size="0.02473 0.0549 0.089265"/>
			</geometry>
   <material name="gray_color">
    <color rgba="0.9 0.9 0.9 1"/>
   </material>
  </visual>
  <collision>
   <origin rpy="0 0 0" xyz="0 0 0.0345175"/>
			<geometry>
    <box size="0.02473 0.0549 0.089265"/>
			</geometry>
  </collision>
 </link>
 
 <joint name="joint4" type="revolute">
  <parent link="forearm"/>
  <child link="hand"/>
  <origin rpy="0 0 0" xyz="0 0 0.10"/>
  <axis xyz="0 1 0"/>
  <limit lower="-1.5708" upper="1.5708" effort="0" velocity="0"/>
 </joint>
 
 <link name="finger">
  <visual name="finger_visual">
   <origin rpy="0 0 0" xyz="0 0.026 0.04"/>
			<geometry>
    <box size="0.025 0.005 0.09"/>
			</geometry>
		</visual>
  <collision>
   <origin rpy="0 0 0" xyz="0 0.026 0.04"/>
			<geometry>
    <box size="0.025 0.005 0.09"/>
			</geometry>
  </collision>
	</link>

	<joint name="finger_joint" type="revolute">
		<parent link="hand"/>
		<child link="finger"/>
  <origin rpy="0 0 3.14" xyz="0 -0.020615 0.066785"/>
  <limit lower="-0.785" upper="0.785" effort="0" velocity="0"/>
	</joint>
 
 <link name="fixfinger">
  <visual name="fixfinger_visual">
   <origin rpy="0 0 0" xyz="0 0 0.04"/>
   <geometry>
    <box size="0.025 0.005 0.09"/>
   </geometry>
  </visual>
  <collision>
   <origin rpy="0 0 0" xyz="0 0 0.04"/>
   <geometry>
    <box size="0.025 0.005 0.09"/>
   </geometry>
  </collision>
 </link>
 
 <joint name="fixfinger_joint" type="fixed">
  <parent link="hand"/>
  <child link="fixfinger"/>
  <origin rpy="0 0 0" xyz="0 0.036492 0.066785"/>
	</joint>

</robot>
