<?xml version="1.0" encoding="utf-8"?>
<robot name="arm4dof">
	<link name="finger">
		<inertial>
			<mass value="0.1620904614417843"/>
			<origin rpy="0 0 0" xyz="0.017572616560184332 0.02339311441352253 0.026468299189299327"/>
			<inertia ixx="0.00018855700831591377" ixy="-4.830126172258614e-07" ixz="-5.465079275041806e-07" iyy="0.000187250928272303" iyz="-2.5198409207287397e-05" izz="4.281226005568026e-05"/>
		</inertial>
		<collision name="finger_collision">
			<origin rpy="-2.775557561562892e-17 -0.0 -1.6653345369377348e-16" xyz="0.017899999999999687 -0.02061499999999994 -0.28825492591488516"/>
			<geometry>
				<mesh filename="package://arm4dof_description/meshes/finger.stl" scale="1.0 1.0 1.0"/>
			</geometry>
		</collision>
		<visual name="finger_visual">
			<origin rpy="-2.775557561562892e-17 -0.0 -1.6653345369377348e-16" xyz="0.017899999999999687 -0.02061499999999994 -0.28825492591488516"/>
			<geometry>
				<mesh filename="package://arm4dof_description/meshes/finger.stl" scale="1.0 1.0 1.0"/>
			</geometry>
		</visual>
	</link>
	<link name="hand">
		<inertial>
			<mass value="0.751568194075787"/>
			<origin rpy="0 0 0" xyz="-5.6146206526912286e-05 0.014623837021789394 0.050500760679562884"/>
			<inertia ixx="0.0011947772732698923" ixy="4.4418819288698735e-07" ixz="6.960611453683541e-07" iyy="0.0010027580082652434" iyz="0.00020241878082143146" izz="0.0002993282090664248"/>
		</inertial>
		<collision name="hand_collision">
			<origin rpy="-2.775557561562892e-17 -0.0 -1.6653345369377348e-16" xyz="1.7763104897573767e-13 0.017900074085115916 -0.2214699252666839"/>
			<geometry>
				<mesh filename="package://arm4dof_description/meshes/hand.stl" scale="1.0 1.0 1.0"/>
			</geometry>
		</collision>
		<visual name="hand_visual">
			<origin rpy="-2.775557561562892e-17 -0.0 -1.6653345369377348e-16" xyz="1.7763104897573767e-13 0.017900074085115916 -0.2214699252666839"/>
			<geometry>
				<mesh filename="package://arm4dof_description/meshes/hand.stl" scale="1.0 1.0 1.0"/>
			</geometry>
   <material name="gray_color">
    <color rgba="0.9 0.9 0.9 1"/>
   </material>
		</visual>
	</link>
	<link name="base_link">
		<inertial>
			<mass value="0.7502954240514383"/>
			<origin rpy="0 0 0" xyz="-0.004937927523443683 0.009208957460279816 -0.016228081827026272"/>
			<inertia ixx="0.0005378909087315135" ixy="-4.691853279065183e-09" ixz="2.725326277291962e-05" iyy="0.0005961167809316274" iyz="-4.538103118334469e-09" izz="0.0007381464012490534"/>
		</inertial>
		<collision name="base_collision">
			<origin rpy="-2.775557561562892e-17 -0.0 -1.6653345369377348e-16" xyz="-0.00011995981091706379 0.009207659539338428 0.0093276193502555"/>
			<geometry>
				<mesh filename="package://arm4dof_description/meshes/base.stl" scale="1.0 1.0 1.0"/>
			</geometry>
		</collision>
		<visual name="base_visual">
			<origin rpy="-2.775557561562892e-17 -0.0 -1.6653345369377348e-16" xyz="-0.00011995981091706379 0.009207659539338428 0.0093276193502555"/>
			<geometry>
				<mesh filename="package://arm4dof_description/meshes/base.stl" scale="1.0 1.0 1.0"/>
			</geometry>
   <material name="gray_color">
    <color rgba="0.9 0.9 0.9 1"/>
   </material>
		</visual>
	</link>
	<link name="upperarm">
		<inertial>
			<mass value="0.6184540010783673"/>
			<origin rpy="0 0 0" xyz="-1.0714196999224435e-13 0.01776341798186061 0.045784999999999944"/>
			<inertia ixx="0.0007486047984566099" ixy="1.4292386718572913e-18" ixz="1.6409276715201315e-15" iyy="0.0007223304624224873" iyz="1.7329745102934168e-09" izz="8.920848606753288e-05"/>
		</inertial>
		<collision name="upperarm_collision">
			<origin rpy="-2.775557561562892e-17 -0.0 -1.6653345369377348e-16" xyz="-2.0395198117167945e-16 0.017900000000000315 -0.029899925266684148"/>
			<geometry>
				<mesh filename="package://arm4dof_description/meshes/upperarm.stl" scale="1.0 1.0 1.0"/>
			</geometry>
		</collision>
		<visual name="upperarm_visual">
			<origin rpy="-2.775557561562892e-17 -0.0 -1.6653345369377348e-16" xyz="-2.0395198117167945e-16 0.017900000000000315 -0.029899925266684148"/>
			<geometry>
				<mesh filename="package://arm4dof_description/meshes/upperarm.stl" scale="1.0 1.0 1.0"/>
			</geometry>
   <material name="gray_color">
    <color rgba="0.9 0.9 0.9 1"/>
   </material>
		</visual>
	</link>
	<link name="forearm">
		<inertial>
			<mass value="0.13426852980149212"/>
			<origin rpy="0 0 0" xyz="-1.2664836627346299e-16 0.017392442591640973 0.04999999999235616"/>
			<inertia ixx="0.00021911210365257503" ixy="3.8541023671123666e-17" ixz="3.37924133120282e-19" iyy="0.00017873496544186906" iyz="3.1463720517876937e-16" izz="5.0200976219413196e-05"/>
		</inertial>
		<collision name="forearm_collision">
			<origin rpy="-2.775557561562892e-17 -0.0 -1.6653345369377348e-16" xyz="1.7761173662454027e-13 0.017900074085116357 -0.12146992526668443"/>
			<geometry>
				<mesh filename="package://arm4dof_description/meshes/forearm.stl" scale="1.0 1.0 1.0"/>
			</geometry>
		</collision>
		<visual name="forearm_visual">
			<origin rpy="-2.775557561562892e-17 -0.0 -1.6653345369377348e-16" xyz="1.7761173662454027e-13 0.017900074085116357 -0.12146992526668443"/>
			<geometry>
				<mesh filename="package://arm4dof_description/meshes/forearm.stl" scale="1.0 1.0 1.0"/>
			</geometry>
		</visual>
	</link>
	<link name="shoulder">
		<inertial>
			<mass value="0.07247169619111539"/>
			<origin rpy="0 0 0" xyz="2.1224455264886037e-08 -0.00043686829965988196 0.015614732084708382"/>
			<inertia ixx="2.7250025071365297e-05" ixy="2.1242883253228678e-13" ixz="-6.3137054992588175e-12" iyy="1.3689070309561062e-05" iyz="3.4429038406645353e-07" izz="1.898341756723466e-05"/>
		</inertial>
		<collision name="shoulder_collision">
			<origin rpy="-2.775557561562892e-17 -0.0 -1.6653345369377348e-16" xyz="2.7934011985787112e-08 1.734723475976807e-18 0.00020007408511598865"/>
			<geometry>
				<mesh filename="package://arm4dof_description/meshes/shoulder.stl" scale="1.0 1.0 1.0"/>
			</geometry>
		</collision>
		<visual name="shoulder_visual">
			<origin rpy="-2.775557561562892e-17 -0.0 -1.6653345369377348e-16" xyz="2.7934011985787112e-08 1.734723475976807e-18 0.00020007408511598865"/>
			<geometry>
				<mesh filename="package://arm4dof_description/meshes/shoulder.stl" scale="1.0 1.0 1.0"/>
			</geometry>
		</visual>
	</link>
	<joint name="finger_joint" type="revolute">
		<parent link="hand"/>
		<child link="finger"/>
		<origin rpy="0 0 0" xyz="-0.017899999999822058 0.038515074085115855 0.06678500064820125"/>
		<axis xyz="-1.0000000000000007 -5.5511151231176124e-17 -7.216449660063521e-16"/>
  <limit lower="-0.785" upper="0.785" effort="0" velocity="0"/>
	</joint>
	<joint name="joint1" type="revolute">
		<parent link="forearm"/>
		<child link="hand"/>
		<origin rpy="0 0 0" xyz="-1.9312351197398048e-17 4.388850394221322e-16 0.09999999999999948"/>
		<axis xyz="5.469212746514901e-15 -0.9999999999999988 4.0132109545040804e-15"/>
  <limit lower="-2.355" upper="2.355" effort="0" velocity="0"/>
	</joint>
	<joint name="joint2" type="revolute">
		<parent link="upperarm"/>
		<child link="forearm"/>
		<origin rpy="0 0 0" xyz="-1.7781568860571195e-13 -7.408511604189982e-08 0.09157000000000029"/>
		<axis xyz="-4.56250541873071e-15 -0.9999999999999984 4.013210954504077e-15"/>
  <limit lower="-2.355" upper="2.355" effort="0" velocity="0"/>
	</joint>
	<joint name="joint3" type="revolute">
		<parent link="shoulder"/>
		<child link="upperarm"/>
		<origin rpy="0 0 0" xyz="2.7934012189739094e-08 -0.01790000000000031 0.030099999351800136"/>
		<axis xyz="4.9960036108131995e-16 -0.9999999999999996 1.1662307446965333e-14"/>
  <limit lower="-2.355" upper="2.355" effort="0" velocity="0"/>
	</joint>
	<joint name="joint4" type="revolute">
		<parent link="base_link"/>
		<child link="shoulder"/>
		<origin rpy="0 0 0" xyz="-0.00011998774492904957 0.009207659539338426 0.009127545265139512"/>
		<axis xyz="1.1102230246251564e-16 -2.7660707925536432e-17 0.9999999999999997"/>
  <limit lower="-3.14" upper="3.14" effort="0" velocity="0"/>
	</joint>
</robot>
